## try...catch
### 仅对运行时的error有效
要使得 try...catch 能工作，代码必须是可执行的。换句话说，它必须是有效的 JavaScript 代码。
如果代码包含语法错误，那么 try..catch 将无法正常工作，例如含有不匹配的花括号：
```javascript
try {
  {{{{{{{{{{{{
} catch (err) {
  alert("引擎无法理解这段代码，它是无效的");
}
```
### ⭐️它是同步执行的
```javascript
try {
  setTimeout(function() {
    noSuchVariable; // 脚本将在这里停止运行
  }, 1000);
} catch (err) {
  alert( "不工作" );
}
```
为了捕获到计划的（scheduled）函数中的异常，那么 try...catch 必须在这个函数内：
```javascript
setTimeout(function() {
  try {
    noSuchVariable; // try...catch 处理 error 了！
  } catch {
    alert( "error 被在这里捕获了！" );
  }
}, 1000);
```
### Error对象
```javascript
try {
  // ...
} catch (err) { // <-- “error 对象”，也可以用其他参数名代替 err
  // ...
}
```
对于所有内建的 error，error 对象具有两个主要属性：

- name
- message
- stack 错误调用栈
### 可选的catch绑定
这是一个最近添加到 JavaScript 的特性。 旧式浏览器可能需要 polyfills.
如果我们不需要 error 的详细信息，catch 也可以忽略它：
```javascript
try {
  // ...
} catch { // <-- 没有 (err)
  // ...
}
```
### throw操作符
throw 操作符会生成一个 error 对象。
技术上讲，我们可以将任何东西用作 error 对象。甚至可以是一个原始类型数据，例如数字或字符串，但最好使用对象，最好使用具有 name 和 message 属性的对象（某种程度上保持与内建 error 的兼容性）。
JavaScript 中有很多内建的标准 error 的构造器：Error，SyntaxError，ReferenceError，TypeError 等。我们也可以使用它们来创建 error 对象。
语法是
```javascript
let error = new Error(message);
// 或
let error = new SyntaxError(message);
let error = new ReferenceError(message);
```
### 再次抛出
“再次抛出（rethrowing）”技术可以被更详细地解释为：

1. Catch 捕获所有 error。
2. 在 catch (err) {...} 块中，我们对 error 对象 err 进行分析。
3. 如果我们不知道如何处理它，那我们就 throw err。
```javascript
try {
  user = { /*...*/ };
} catch (err) {
  if (err instanceof ReferenceError) {
    alert('ReferenceError'); // 访问一个未定义（undefined）的变量产生了 "ReferenceError"
  }
}
```
### try…catch…finally
如果它存在，它在所有情况下都会被执行：

- try 之后，如果没有 error，
- catch 之后，如果有 error。
```javascript
try {
  alert( 'try' );
  if (confirm('Make an error?')) BAD_CODE();
} catch (err) {
  alert( 'catch' );
} finally {
  alert( 'finally' );
}
```
这段代码有两种执行方式：

1. 如果你对于 “Make an error?” 的回答是 “Yes”，那么执行 try -> catch -> finally。
2. 如果你的回答是 “No”，那么执行 try -> finally。

finally 子句（clause）通常用在：当我们开始做某事的时候，希望无论出现什么情况都要完成完成某个任务。
在下面这个例子中，在 try 中有一个 return。在这种情况下，finally 会在控制转向外部代码前被执行
```javascript
function func() {

  try {
    return 1;

  } catch (err) {
    /* ... */
  } finally {
    alert( 'finally' );
  }
}

alert( func() ); // 先执行 finally 中的 alert，然后执行这个 alert
```
### window.onerror
全局错误处理程序 window.onerror 的作用通常不是恢复脚本的执行 —— 如果发生编程错误，恢复脚本的执行几乎是不可能的，它的作用是将错误信息发送给开发者。
## 常见错误类型
### SyntaxError 对象
`SyntaxError`对象是解析代码时发生的语法错误。
```javascript
// 变量名错误
var 1a;
// Uncaught SyntaxError: Invalid or unexpected token

// 缺少括号
console.log 'hello');
// Uncaught SyntaxError: Unexpected string
```
### ReferenceError 对象
`ReferenceError`对象是引用一个不存在的变量时发生的错误。
```javascript
// 使用一个不存在的变量
unknownVariable
// Uncaught ReferenceError: unknownVariable is not defined

// 另外
// 等号左侧不是变量
console.log() = 1
// Uncaught ReferenceError: Invalid left-hand side in assignment
```
### RangeError 对象
`RangeError`对象是一个值超出有效范围时发生的错误。主要有几种情况，一是数组长度为负数，二是Number对象的方法参数超出范围，以及函数堆栈超过最大值。
```javascript
// 数组长度不得为负数
new Array(-1)
// Uncaught RangeError: Invalid array length
```
### TypeError 对象 
`TypeError`对象是变量或参数不是预期类型时发生的错误
```javascript
new 123
// Uncaught TypeError: 123 is not a constructor

var obj = {};
obj.unknownMethod()
// Uncaught TypeError: obj.unknownMethod is not a function
```
## throw 语句
```javascript
var x = -1;

if (x <= 0) {
  throw new Error('x 必须为正数');
}
// Uncaught Error: x 必须为正数
```
## 自定义Error
当我们在开发某些东西时，经常会需要我们自己的 error 类来反映在我们的任务中可能出错的特定任务。对于网络操作中的 error，我们需要 HttpError，对于数据库操作中的 error，我们需要 DbError，对于搜索操作中的 error，我们需要 NotFoundError，等等。
### 一个示例
```javascript
// JavaScript 自身定义的内建的 Error 类的“伪代码”
class Error {
  constructor(message) {
    this.message = message;
    this.name = "Error"; // (不同的内建 error 类有不同的名字)
    this.stack = <call stack>; // 非标准的，但大多数环境都支持它
  }
}


class ValidationError extends Error {
  constructor(message) {
    super(message);
    this.name = "ValidationError";
  }
}

// 用法
function readUser(json) {
  let user = JSON.parse(json);

  if (!user.age) {
    throw new ValidationError("No field: age");
  }
  if (!user.name) {
    throw new ValidationError("No field: name");
  }

  return user;
}

// try..catch 的工作示例

try {
  let user = readUser('{ "age": 25 }');
} catch (err) {
  if (err instanceof ValidationError) {
    alert("Invalid data: " + err.message); // Invalid data: No field: name
  } else if (err instanceof SyntaxError) { // (*)
    alert("JSON Syntax Error: " + err.message);
  } else {
    throw err; // 未知的 error，再次抛出 (**)
  }
}
```
详细应用见：[自定义 Error，扩展 Error](https://zh.javascript.info/custom-errors)
## 问题
### try里面放return
```javascript

function foo(){
  try{
    return 0;
  } catch(err) {

  } finally {
    return 1;
  }
}

console.log(foo());  // 1
```




## 
## 资料

- [https://zh.javascript.info/try-catch](https://zh.javascript.info/try-catch)
- [https://zh.javascript.info/custom-errors](https://zh.javascript.info/custom-errors)
- [https://wangdoc.com/javascript/features/error](https://wangdoc.com/javascript/features/error)
